<?xml version="1.0"?>
<robot xmlns:xacro="http://www.ros.org/wiki/xacro" name="carryall">

  <!-- ==================== PROPERTIES ==================== -->
  <xacro:property name="wheel_radius" value="0.1"/>     <!-- 10cm wheel radius -->
  <xacro:property name="wheel_width" value="0.05"/>     <!-- 5cm wheel width -->
  <xacro:property name="wheel_separation" value="0.5"/> <!-- 50cm between wheels -->
  <xacro:property name="base_length" value="0.6"/>      <!-- 60cm length -->
  <xacro:property name="base_width" value="0.4"/>      <!-- 40cm width -->
  <xacro:property name="base_height" value="0.2"/>      <!-- 20cm height -->
  <xacro:property name="base_mass" value="20.0"/>       <!-- 20kg base mass -->

  <!-- ==================== BASE LINK ==================== -->
  <link name="base_link">
    <visual>
      <geometry>
        <box size="${base_length} ${base_width} ${base_height}"/>
      </geometry>
      <material name="gray">
        <color rgba="0.5 0.5 0.5 1.0"/>
      </material>
    </visual>
    <collision>
      <geometry>
        <box size="${base_length} ${base_width} ${base_height}"/>
      </geometry>
    </collision>
    <inertial>
      <mass value="${base_mass}"/>
      <inertia ixx="0.5" ixy="0" ixz="0" iyy="0.8" iyz="0" izz="0.5"/>
    </inertial>
  </link>

  <!-- ==================== LEFT WHEEL ==================== -->
  <link name="left_wheel">
    <visual>
      <geometry>
        <cylinder radius="${wheel_radius}" length="${wheel_width}"/>
      </geometry>
      <material name="black">
        <color rgba="0.1 0.1 0.1 1.0"/>
      </material>
    </visual>
    <collision>
      <geometry>
        <cylinder radius="${wheel_radius}" length="${wheel_width}"/>
      </geometry>
    </collision>
    <inertial>
      <mass value="1.0"/>
      <inertia ixx="0.01" ixy="0" ixz="0" iyy="0.005" iyz="0" izz="0.01"/>
    </inertial>
  </link>

  <joint name="left_wheel_joint" type="continuous">
    <parent link="base_link"/>
    <child link="left_wheel"/>
    <origin xyz="0 ${wheel_separation/2} 0" rpy="${-pi/2} 0 0"/>
    <axis xyz="0 0 1"/>
  </joint>

  <!-- ==================== RIGHT WHEEL ==================== -->
  <link name="right_wheel">
    <visual>
      <geometry>
        <cylinder radius="${wheel_radius}" length="${wheel_width}"/>
      </geometry>
      <material name="black">
        <color rgba="0.1 0.1 0.1 1.0"/>
      </material>
    </visual>
    <collision>
      <geometry>
        <cylinder radius="${wheel_radius}" length="${wheel_width}"/>
      </geometry>
    </collision>
    <inertial>
      <mass value="1.0"/>
      <inertia ixx="0.01" ixy="0" ixz="0" iyy="0.005" iyz="0" izz="0.01"/>
    </inertial>
  </link>

  <joint name="right_wheel_joint" type="continuous">
    <parent link="base_link"/>
    <child link="right_wheel"/>
    <origin xyz="0 ${-wheel_separation/2} 0" rpy="${-pi/2} 0 0"/>
    <axis xyz="0 0 1"/>
  </joint>

  <!-- ==================== CASTER WHEEL (FRONT) ==================== -->
  <link name="caster_wheel">
    <visual>
      <geometry>
        <sphere radius="0.05"/>
      </geometry>
      <material name="black">
        <color rgba="0.1 0.1 0.1 1.0"/>
      </material>
    </visual>
    <collision>
      <geometry>
        <sphere radius="0.05"/>
      </geometry>
    </collision>
  </link>

  <joint name="caster_wheel_joint" type="fixed">
    <parent link="base_link"/>
    <child link="caster_wheel"/>
    <origin xyz="${base_length/3} 0 ${-wheel_radius + 0.05}" rpy="0 0 0"/>
  </joint>

  <!-- ==================== CASTER WHEEL (REAR) ==================== -->
  <link name="caster_wheel_rear">
    <visual>
      <geometry>
        <sphere radius="0.05"/>
      </geometry>
      <material name="black">
        <color rgba="0.1 0.1 0.1 1.0"/>
      </material>
    </visual>
    <collision>
      <geometry>
        <sphere radius="0.05"/>
      </geometry>
    </collision>
  </link>

  <joint name="caster_wheel_rear_joint" type="fixed">
    <parent link="base_link"/>
    <child link="caster_wheel_rear"/>
    <origin xyz="${-base_length/3} 0 ${-wheel_radius + 0.05}" rpy="0 0 0"/>
  </joint>

  <!-- Include sensors -->
  <xacro:include filename="$(find carryall_description)/urdf/sensors.xacro"/>

</robot>
